HTTPConnectionPool(host='typesense', port=8108): Max retries exceeded with url: /collections/DOID/documents/search?q=malign+neoplasm+lung&query_by=diseaseName%2C+definition&sort_by=_text_match%3Adesc&num_typos=0 (Caused by NewConnectionError('<urllib3.connection.HTTPConnection object at 0x286370cd0>: Failed to establish a new connection: [Errno 8] nodename nor servname provided, or not known'))annotation_context.py 2022-09-03 13:35:46.490502 HTTPConnectionPool(host='typesense', port=8108): Max retries exceeded with url: /collections (Caused by NewConnectionError('<urllib3.connection.HTTPConnection object at 0x1737363a0>: Failed to establish a new connection: [Errno 8] nodename nor servname provided, or not known'))
views.py 2022-09-03 13:35:51.018564 HTTPConnectionPool(host='typesense', port=8108): Max retries exceeded with url: /collections/DOID/documents/search?q=malign+neoplasm+lung&query_by=diseaseName%2C+definition&sort_by=_text_match%3Adesc&num_typos=0 (Caused by NewConnectionError('<urllib3.connection.HTTPConnection object at 0x28cdddc40>: Failed to establish a new connection: [Errno 8] nodename nor servname provided, or not known'))
annotation_context.py 2022-09-05 15:58:51.933651 HTTPConnectionPool(host='typesense', port=8108): Max retries exceeded with url: /collections (Caused by NewConnectionError('<urllib3.connection.HTTPConnection object at 0x172f73040>: Failed to establish a new connection: [Errno 8] nodename nor servname provided, or not known'))
views.py 2022-09-05 15:58:56.500335 HTTPConnectionPool(host='typesense', port=8108): Max retries exceeded with url: /collections/DOID/documents/search?q=malign+neoplasm+lung&query_by=diseaseName%2C+definition&sort_by=_text_match%3Adesc&num_typos=0 (Caused by NewConnectionError('<urllib3.connection.HTTPConnection object at 0x28445bb80>: Failed to establish a new connection: [Errno 8] nodename nor servname provided, or not known'))
annotation_context.py 2022-09-05 16:39:12.583703 HTTPConnectionPool(host='typesense', port=8108): Max retries exceeded with url: /collections (Caused by NewConnectionError('<urllib3.connection.HTTPConnection object at 0x13eb127f0>: Failed to establish a new connection: [Errno 8] nodename nor servname provided, or not known'))
views.py 2022-09-05 16:39:17.116704 HTTPConnectionPool(host='typesense', port=8108): Max retries exceeded with url: /collections/DOID/documents/search?q=malign+neoplasm+lung&query_by=diseaseName%2C+definition&sort_by=_text_match%3Adesc&num_typos=0 (Caused by NewConnectionError('<urllib3.connection.HTTPConnection object at 0x156498220>: Failed to establish a new connection: [Errno 8] nodename nor servname provided, or not known'))
annotation_context.py 2022-09-05 16:42:37.542123 HTTPConnectionPool(host='typesense', port=8108): Max retries exceeded with url: /collections (Caused by NewConnectionError('<urllib3.connection.HTTPConnection object at 0x15622ac70>: Failed to establish a new connection: [Errno 8] nodename nor servname provided, or not known'))
views.py 2022-09-05 16:42:41.842342 HTTPConnectionPool(host='typesense', port=8108): Max retries exceeded with url: /collections/DOID/documents/search?q=malign+neoplasm+lung&query_by=diseaseName%2C+definition&sort_by=_text_match%3Adesc&num_typos=0 (Caused by NewConnectionError('<urllib3.connection.HTTPConnection object at 0x2885f8c40>: Failed to establish a new connection: [Errno 8] nodename nor servname provided, or not known'))
annotation_context.py 2022-09-05 16:47:44.261866 HTTPConnectionPool(host='typesense', port=8108): Max retries exceeded with url: /collections (Caused by NewConnectionError('<urllib3.connection.HTTPConnection object at 0x168455d30>: Failed to establish a new connection: [Errno 8] nodename nor servname provided, or not known'))
views.py 2022-09-05 16:47:48.827125 HTTPConnectionPool(host='typesense', port=8108): Max retries exceeded with url: /collections/DOID/documents/search?q=malign+neoplasm+lung&query_by=diseaseName%2C+definition&sort_by=_text_match%3Adesc&num_typos=0 (Caused by NewConnectionError('<urllib3.connection.HTTPConnection object at 0x2852013d0>: Failed to establish a new connection: [Errno 8] nodename nor servname provided, or not known'))
annotation_context.py 2022-09-05 16:58:41.605881 HTTPConnectionPool(host='typesense', port=8108): Max retries exceeded with url: /collections (Caused by NewConnectionError('<urllib3.connection.HTTPConnection object at 0x172a71040>: Failed to establish a new connection: [Errno 8] nodename nor servname provided, or not known'))
views.py 2022-09-05 16:58:46.092859 HTTPConnectionPool(host='typesense', port=8108): Max retries exceeded with url: /collections/DOID/documents/search?q=malign+neoplasm+lung&query_by=diseaseName%2C+definition&sort_by=_text_match%3Adesc&num_typos=0 (Caused by NewConnectionError('<urllib3.connection.HTTPConnection object at 0x289eb1cd0>: Failed to establish a new connection: [Errno 8] nodename nor servname provided, or not known'))
annotation_context.py 2022-09-06 09:54:49.818097 [Errno 401] Forbidden - a valid `x-typesense-api-key` header must be sent.
views.py 2022-09-06 09:54:51.325179 [Errno 401] Forbidden - a valid `x-typesense-api-key` header must be sent.
annotation_context.py 2022-09-06 09:56:56.162589 [Errno 401] Forbidden - a valid `x-typesense-api-key` header must be sent.
views.py 2022-09-06 09:56:58.428754 [Errno 401] Forbidden - a valid `x-typesense-api-key` header must be sent.
annotation_context.py 2022-09-06 10:02:30.103425 [Errno 401] Forbidden - a valid `x-typesense-api-key` header must be sent.
views.py 2022-09-06 10:02:31.591372 [Errno 401] Forbidden - a valid `x-typesense-api-key` header must be sent.
annotation_context.py 2022-09-06 10:20:19.670072 [Errno 401] Forbidden - a valid `x-typesense-api-key` header must be sent.
views.py 2022-09-06 10:20:21.954146 [Errno 401] Forbidden - a valid `x-typesense-api-key` header must be sent.
annotation_context.py 2022-09-09 21:06:58.003342 [Errno 401] Forbidden - a valid `x-typesense-api-key` header must be sent.
views.py 2022-09-09 21:07:00.444641 [Errno 401] Forbidden - a valid `x-typesense-api-key` header must be sent.
annotation_context.py 2022-09-09 21:13:32.157286 [Errno 401] Forbidden - a valid `x-typesense-api-key` header must be sent.
views.py 2022-09-09 21:13:33.723898 [Errno 401] Forbidden - a valid `x-typesense-api-key` header must be sent.
